Workbook

Sheet DetalleSaldosBancosFinal
A1: ParentKey | B1: LineNum | C1: AccountCode | D1: ShortName | E1: LineMemo | F1: DueDate | G1: TaxDate | H1: VatDate | I1: U_INFOPE01 | J1: U_INFOPE02 | K1: Reference2 | L1: FCCurrency | M1: Debit | N1: Credit | O1: Reference2 | P1: Reference2 | Q1: ProjectCode | R1: Reference1
A2: 1 | B2: 1 | C2: 94211202 | E2: PL-012507EMN0L | F2: 20260319 | G2: 20260319 | H2: 20260319 | M2: 173 | P2: 307030 | R2: PLANILLA MES DE JULIO 2025
A3: 1 | B3: 2 | C3: 94211202 | E3: PL-012507EMN0L | F3: 20260319 | G3: 20260319 | H3: 20260319 | M3: 96 | P3: 307030 | R3: PLANILLA MES DE JULIO 2025
A4: 1 | B4: 3 | C4: 94221104 | E4: PL-012507EMN0L | F4: 20260319 | G4: 20260319 | H4: 20260319 | M4: 500 | P4: 307030 | R4: PLANILLA MES DE JULIO 2025
A5: 1 | B5: 4 | C5: 94221104 | E5: PL-012507EMN0L | F5: 20260319 | G5: 20260319 | H5: 20260319 | M5: 500 | P5: 307030 | R5: PLANILLA MES DE JULIO 2025
A6: 1 | B6: 5 | C6: 94221104 | E6: PL-012507EMN0L | F6: 20260319 | G6: 20260319 | H6: 20260319 | M6: 500 | P6: 307030 | R6: PLANILLA MES DE JULIO 2025
A7: 1 | B7: 6 | C7: 94221104 | E7: PL-012507EMN0L | F7: 20260319 | G7: 20260319 | H7: 20260319 | M7: 100 | P7: 307030 | R7: PLANILLA MES DE JULIO 2025
A8: 1 | B8: 7 | C8: 94221104 | E8: PL-012507EMN0L | F8: 20260319 | G8: 20260319 | H8: 20260319 | M8: 2480 | P8: 307030 | R8: PLANILLA MES DE JULIO 2025
A9: 1 | B9: 8 | C9: 94221104 | E9: PL-012507EMN0L | F9: 20260319 | G9: 20260319 | H9: 20260319 | M9: 500 | P9: 307030 | R9: PLANILLA MES DE JULIO 2025
A10: 1 | B10: 9 | C10: 94221104 | E10: PL-012507EMN0L | F10: 20260319 | G10: 20260319 | H10: 20260319 | M10: 600 | P10: 307030 | R10: PLANILLA MES DE JULIO 2025
A11: 1 | B11: 10 | C11: 94221104 | E11: PL-012507EMN0L | F11: 20260319 | G11: 20260319 | H11: 20260319 | M11: 500 | P11: 307030 | R11: PLANILLA MES DE JULIO 2025
A12: 1 | B12: 11 | C12: 94221104 | E12: PL-012507EMN0L | F12: 20260319 | G12: 20260319 | H12: 20260319 | M12: 600 | P12: 307030 | R12: PLANILLA MES DE JULIO 2025
A13: 1 | B13: 12 | C13: 94221104 | E13: PL-012507EMN0L | F13: 20260319 | G13: 20260319 | H13: 20260319 | M13: 800 | P13: 307030 | R13: PLANILLA MES DE JULIO 2025
... A15: 1 | B15: 14 | C15: 94221104 | E15: PL-012507EMN0L | F15: 20260319 | G15: 20260319 | H15: 20260319 | M15: 1100 | P15: 307030 | R15: PLANILLA MES DE JULIO 2025
A16: 1 | B16: 15 | C16: 94211402 | E16: PL-012507EMN0L | F16: 20260319 | G16: 20260319 | H16: 20260319 | I16: 813858 | M16: 1185.5 | P16: 307030 | R16: PLANILLA MES DE JULIO 2025
A17: 1 | B17: 16 | C17: 94211402 | E17: PL-012507EMN0L | F17: 20260319 | G17: 20260319 | H17: 20260319 | I17: 23871 | M17: 2518.83 | P17: 307030 | R17: PLANILLA MES DE JULIO 2025
A18: 1 | B18: 17 | C18: 94211105 | E18: PL-012507EMN0L | F18: 20260319 | G18: 20260319 | H18: 20260319 | I18: 9003627 | M18: 250 | P18: 307030 | R18: PLANILLA MES DE JULIO 2025
A19: 1 | B19: 18 | C19: 94211105 | E19: PL-012507EMN0L | F19: 20260319 | G19: 20260319 | H19: 20260319 | I19: 23871 | M19: 500 | P19: 307030 | R19: PLANILLA MES DE JULIO 2025
A20: 1 | B20: 19 | C20: 94221101 | E20: PL-012507EMN0L | F20: 20260319 | G20: 20260319 | H20: 20260319 | M20: 88.26 | P20: 307030 | R20: PLANILLA MES DE JULIO 2025
A21: 1 | B21: 20 | C21: 94221101 | E21: PL-012507EMN0L | F21: 20260319 | G21: 20260319 | H21: 20260319 | M21: 160 | P21: 307030 | R21: PLANILLA MES DE JULIO 2025
A22: 1 | B22: 21 | C22: 94221101 | E22: PL-012507EMN0L | F22: 20260319 | G22: 20260319 | H22: 20260319 | M22: 395.66 | P22: 307030 | R22: PLANILLA MES DE JULIO 2025
A23: 1 | B23: 22 | C23: 94221101 | E23: PL-012507EMN0L | F23: 20260319 | G23: 20260319 | H23: 20260319 | M23: 269.56 | P23: 307030 | R23: PLANILLA MES DE JULIO 2025
A24: 1 | B24: 23 | C24: 94221101 | E24: PL-012507EMN0L | F24: 20260319 | G24: 20260319 | H24: 20260319 | M24: 127.53 | P24: 307030 | R24: PLANILLA MES DE JULIO 2025
A25: 1 | B25: 24 | C25: 94221101 | E25: PL-012507EMN0L | F25: 20260319 | G25: 20260319 | H25: 20260319 | M25: 113.33 | P25: 307030 | R25: PLANILLA MES DE JULIO 2025
A26: 1 | B26: 25 | C26: 94221101 | E26: PL-012507EMN0L | F26: 20260319 | G26: 20260319 | H26: 20260319 | M26: 165.32 | P26: 307030 | R26: PLANILLA MES DE JULIO 2025
A27: 1 | B27: 26 | C27: 94221102 | E27: PL-012507EMN0L | F27: 20260319 | G27: 20260319 | H27: 20260319 | I27: 854196 | M27: 300 | P27: 307030 | R27: PLANILLA MES DE JULIO 2025
A28: 1 | B28: 27 | C28: 94221102 | E28: PL-012507EMN0L | F28: 20260319 | G28: 20260319 | H28: 20260319 | I28: 639936 | M28: 300 | P28: 307030 | R28: PLANILLA MES DE JULIO 2025
A29: 1 | B29: 28 | C29: 94221102 | E29: PL-012507EMN0L | F29: 20260319 | G29: 20260319 | H29: 20260319 | I29: 875739 | M29: 250 | P29: 307030 | R29: PLANILLA MES DE JULIO 2025
A30: 1 | B30: 29 | C30: 94221102 | E30: PL-012507EMN0L | F30: 20260319 | G30: 20260319 | H30: 20260319 | I30: 862486 | M30: 1000 | P30: 307030 | R30: PLANILLA MES DE JULIO 2025
A31: 1 | B31: 30 | C31: 94221102 | E31: PL-012507EMN0L | F31: 20260319 | G31: 20260319 | H31: 20260319 | I31: 25191 | M31: 250 | P31: 307030 | R31: PLANILLA MES DE JULIO 2025
A32: 1 | B32: 31 | C32: 94211602 | E32: PL-012507EMN0L | F32: 20260319 | G32: 20260319 | H32: 20260319 | I32: 813858 | M32: 106.7 | P32: 307030 | R32: PLANILLA MES DE JULIO 2025
A33: 1 | B33: 32 | C33: 94211602 | E33: PL-012507EMN0L | F33: 20260319 | G33: 20260319 | H33: 20260319 | I33: 23871 | M33: 170.02 | P33: 307030 | R33: PLANILLA MES DE JULIO 2025
A34: 1 | B34: 33 | C34: 94271101 | E34: PL-012507EMN0L | F34: 20260319 | G34: 20260319 | H34: 20260319 | I34: 688044 | M34: 550.17 | P34: 307030 | R34: PLANILLA MES DE JULIO 2025
A35: 1 | B35: 34 | C35: 94271101 | E35: PL-012507EMN0L | F35: 20260319 | G35: 20260319 | H35: 20260319 | I35: 728773 | M35: 289.17 | P35: 307030 | R35: PLANILLA MES DE JULIO 2025
A36: 1 | B36: 35 | C36: 94271101 | E36: PL-012507EMN0L | F36: 20260319 | G36: 20260319 | H36: 20260319 | I36: 776438 | M36: 247.25 | P36: 307030 | R36: PLANILLA MES DE JULIO 2025
A37: 1 | B37: 36 | C37: 94271101 | E37: PL-012507EMN0L | F37: 20260319 | G37: 20260319 | H37: 20260319 | I37: 839240 | M37: 910.17 | P37: 307030 | R37: PLANILLA MES DE JULIO 2025
A38: 1 | B38: 37 | C38: 94271101 | E38: PL-012507EMN0L | F38: 20260319 | G38: 20260319 | H38: 20260319 | I38: 870084 | M38: 288 | P38: 307030 | R38: PLANILLA MES DE JULIO 2025
A39: 1 | B39: 778 | C39: 95271101 | E39: PL-012507EMN0L | F39: 20260319 | G39: 20260319 | H39: 20260319 | I39: 753482 | M39: 356.76 | P39: 307030 | R39: PLANILLA MES DE JULIO 2025
A40: 1 | B40: 779 | C40: 95271101 | E40: PL-012507EMN0L | F40: 20260319 | G40: 20260319 | H40: 20260319 | I40: 24589 | M40: 290.97 | P40: 307030 | R40: PLANILLA MES DE JULIO 2025
A41: 1 | B41: 780 | C41: 95271101 | E41: PL-012507EMN0L | F41: 20260319 | G41: 20260319 | H41: 20260319 | I41: 24622 | M41: 111.24 | P41: 307030 | R41: PLANILLA MES DE JULIO 2025
...

Sheet DetalleSaldosBancosFinal1
A1: ParentKey | B1: LineNum | C1: AccountCode | D1: LineMemo | E1: DueDate | F1: TaxDate | G1: VatDate | H1: FCCurrency | I1: Debit | J1: Credit | K1: FCDebit | L1: FCCredit | M1: DebitSys | N1: CreditSys | O1: Reference2 | P1: AdditionalReference | Q1: BaseSum | R1: ContraAccount | S1: CostingCode | T1: GrossValue | U1: ProjectCode | V1: Reference1 | W1: ReferenceDate1 | X1: ReferenceDate2 | Y1: ShortName | Z1: SystemBaseAmount | AA1: SystemVatAmount | AB1: TaxGroup | AC1: VatAmount | AD1: VatLine | AE1: U_BPP_CTAD
A2: Correlativo | B2: Numero de Linea | C2: Cuenta Contable | D2: Observaciones | E2: Fecha de Contabilizacion | F2: Fecha de Documento | G2: Fecha de Vencimiento | H2: Moneda | I2: Debe Soles | J2: Haber Soles | K2: Debe Dolares | L2: Haber Dolares | M2: Debe Sistema | N2: Haber Sistema | O2: Reference2 | P2: AdditionalReference | Q2: BaseSum | R2: ContraAccount | S2: CostingCode | T2: GrossValue | U2: ProjectCode | V2: Reference1 | W2: ReferenceDate1 | X2: ReferenceDate2 | Y2: ShortName | Z2: SystemBaseAmount | AA2: SystemVatAmount | AB2: TaxGroup | AC2: VatAmount | AD2: VatLine | AE2: Cta Destino | AF2: CargoSoles | AG2: AbonoSoles
A3: 1 | B3: 0 | C3: 1011101 | E3: 20130630 | F3: 20130630 | G3: 20130630 | I3: 33140.96 | AF3: =IF(I3="",0-IF(VLOOKUP(C3,BalanceComprobacion!B:G,5,FALSE)="",0,VLOOKUP(C3,BalanceComprobacion!B:G,5,FALSE)),DetalleSaldosBancosFinal1!I3-IF(VLOOKUP(DetalleSaldosBancosFinal1!C3,BalanceComprobacion!B:G,5,FALSE)="",0,VLOOKUP(DetalleSaldosBancosFinal1!C3,BalanceComprobacion!B:G,5,FALSE))) -> #N/A | AG3: =IF(J3="",0-IF(VLOOKUP(C3,BalanceComprobacion!B:G,6,FALSE)="",0,VLOOKUP(C3,BalanceComprobacion!B:G,6,FALSE)),DetalleSaldosBancosFinal1!J3-IF(VLOOKUP(DetalleSaldosBancosFinal1!C3,BalanceComprobacion!B:G,6,FALSE)="",0,VLOOKUP(DetalleSaldosBancosFinal1!C3,BalanceComprobacion!B:G,6,FALSE))) -> #N/A
A4: 1 | B4: 1 | C4: 1021101 | E4: 20130630 | F4: 20130630 | G4: 20130630 | I4: 2500 | AF4: =IF(I4="",0-IF(VLOOKUP(C4,BalanceComprobacion!B:G,5,FALSE)="",0,VLOOKUP(C4,BalanceComprobacion!B:G,5,FALSE)),DetalleSaldosBancosFinal1!I4-IF(VLOOKUP(DetalleSaldosBancosFinal1!C4,BalanceComprobacion!B:G,5,FALSE)="",0,VLOOKUP(DetalleSaldosBancosFinal1!C4,BalanceComprobacion!B:G,5,FALSE))) -> #N/A | AG4: =IF(J4="",0-IF(VLOOKUP(C4,BalanceComprobacion!B:G,6,FALSE)="",0,VLOOKUP(C4,BalanceComprobacion!B:G,6,FALSE)),DetalleSaldosBancosFinal1!J4-IF(VLOOKUP(DetalleSaldosBancosFinal1!C4,BalanceComprobacion!B:G,6,FALSE)="",0,VLOOKUP(DetalleSaldosBancosFinal1!C4,BalanceComprobacion!B:G,6,FALSE))) -> #N/A
A5: 1 | B5: 2 | C5: 1041107 | E5: 20130630 | F5: 20130630 | G5: 20130630 | I5: 163954 | AF5: =IF(I5="",0-IF(VLOOKUP(C5,BalanceComprobacion!B:G,5,FALSE)="",0,VLOOKUP(C5,BalanceComprobacion!B:G,5,FALSE)),DetalleSaldosBancosFinal1!I5-IF(VLOOKUP(DetalleSaldosBancosFinal1!C5,BalanceComprobacion!B:G,5,FALSE)="",0,VLOOKUP(DetalleSaldosBancosFinal1!C5,BalanceComprobacion!B:G,5,FALSE))) -> #N/A | AG5: =IF(J5="",0-IF(VLOOKUP(C5,BalanceComprobacion!B:G,6,FALSE)="",0,VLOOKUP(C5,BalanceComprobacion!B:G,6,FALSE)),DetalleSaldosBancosFinal1!J5-IF(VLOOKUP(DetalleSaldosBancosFinal1!C5,BalanceComprobacion!B:G,6,FALSE)="",0,VLOOKUP(DetalleSaldosBancosFinal1!C5,BalanceComprobacion!B:G,6,FALSE))) -> #N/A
A6: 1 | B6: 3 | C6: 1041110 | E6: 20130630 | F6: 20130630 | G6: 20130630 | J6: 102576.83 | AF6: =IF(I6="",0-IF(VLOOKUP(C6,BalanceComprobacion!B:G,5,FALSE)="",0,VLOOKUP(C6,BalanceComprobacion!B:G,5,FALSE)),DetalleSaldosBancosFinal1!I6-IF(VLOOKUP(DetalleSaldosBancosFinal1!C6,BalanceComprobacion!B:G,5,FALSE)="",0,VLOOKUP(DetalleSaldosBancosFinal1!C6,BalanceComprobacion!B:G,5,FALSE))) -> #N/A | AG6: =IF(J6="",0-IF(VLOOKUP(C6,BalanceComprobacion!B:G,6,FALSE)="",0,VLOOKUP(C6,BalanceComprobacion!B:G,6,FALSE)),DetalleSaldosBancosFinal1!J6-IF(VLOOKUP(DetalleSaldosBancosFinal1!C6,BalanceComprobacion!B:G,6,FALSE)="",0,VLOOKUP(DetalleSaldosBancosFinal1!C6,BalanceComprobacion!B:G,6,FALSE))) -> #N/A
A7: 1 | B7: 4 | C7: 1041101 | E7: 20130630 | F7: 20130630 | G7: 20130630 | J7: 135406.37 | AF7: =IF(I7="",0-IF(VLOOKUP(C7,BalanceComprobacion!B:G,5,FALSE)="",0,VLOOKUP(C7,BalanceComprobacion!B:G,5,FALSE)),DetalleSaldosBancosFinal1!I7-IF(VLOOKUP(DetalleSaldosBancosFinal1!C7,BalanceComprobacion!B:G,5,FALSE)="",0,VLOOKUP(DetalleSaldosBancosFinal1!C7,BalanceComprobacion!B:G,5,FALSE))) -> #N/A | AG7: =IF(J7="",0-IF(VLOOKUP(C7,BalanceComprobacion!B:G,6,FALSE)="",0,VLOOKUP(C7,BalanceComprobacion!B:G,6,FALSE)),DetalleSaldosBancosFinal1!J7-IF(VLOOKUP(DetalleSaldosBancosFinal1!C7,BalanceComprobacion!B:G,6,FALSE)="",0,VLOOKUP(DetalleSaldosBancosFinal1!C7,BalanceComprobacion!B:G,6,FALSE))) -> #N/A
A8: 1 | B8: 5 | C8: 1042101 | E8: 20130630 | F8: 20130630 | G8: 20130630 | J8: 3787.69 | AF8: =IF(I8="",0-IF(VLOOKUP(C8,BalanceComprobacion!B:G,5,FALSE)="",0,VLOOKUP(C8,BalanceComprobacion!B:G,5,FALSE)),DetalleSaldosBancosFinal1!I8-IF(VLOOKUP(DetalleSaldosBancosFinal1!C8,BalanceComprobacion!B:G,5,FALSE)="",0,VLOOKUP(DetalleSaldosBancosFinal1!C8,BalanceComprobacion!B:G,5,FALSE))) -> #N/A | AG8: =IF(J8="",0-IF(VLOOKUP(C8,BalanceComprobacion!B:G,6,FALSE)="",0,VLOOKUP(C8,BalanceComprobacion!B:G,6,FALSE)),DetalleSaldosBancosFinal1!J8-IF(VLOOKUP(DetalleSaldosBancosFinal1!C8,BalanceComprobacion!B:G,6,FALSE)="",0,VLOOKUP(DetalleSaldosBancosFinal1!C8,BalanceComprobacion!B:G,6,FALSE))) -> #N/A
A9: 1 | B9: 6 | C9: 1062101 | E9: 20130630 | F9: 20130630 | G9: 20130630 | I9: 515904.17 | AF9: =IF(I9="",0-IF(VLOOKUP(C9,BalanceComprobacion!B:G,5,FALSE)="",0,VLOOKUP(C9,BalanceComprobacion!B:G,5,FALSE)),DetalleSaldosBancosFinal1!I9-IF(VLOOKUP(DetalleSaldosBancosFinal1!C9,BalanceComprobacion!B:G,5,FALSE)="",0,VLOOKUP(DetalleSaldosBancosFinal1!C9,BalanceComprobacion!B:G,5,FALSE))) -> #N/A | AG9: =IF(J9="",0-IF(VLOOKUP(C9,BalanceComprobacion!B:G,6,FALSE)="",0,VLOOKUP(C9,BalanceComprobacion!B:G,6,FALSE)),DetalleSaldosBancosFinal1!J9-IF(VLOOKUP(DetalleSaldosBancosFinal1!C9,BalanceComprobacion!B:G,6,FALSE)="",0,VLOOKUP(DetalleSaldosBancosFinal1!C9,BalanceComprobacion!B:G,6,FALSE))) -> #N/A
A10: 1 | B10: 6 | C10: 9901 | D10: Cuenta de Cierre de Bancos SOL | E10: 20130630 | F10: 20130630 | G10: 20130630 | J10: 473728.24 | AF10: =IF(I10="",0-IF(VLOOKUP(C10,BalanceComprobacion!B:G,5,FALSE)="",0,VLOOKUP(C10,BalanceComprobacion!B:G,5,FALSE)),DetalleSaldosBancosFinal1!I10-IF(VLOOKUP(DetalleSaldosBancosFinal1!C10,BalanceComprobacion!B:G,5,FALSE)="",0,VLOOKUP(DetalleSaldosBancosFinal1!C10,BalanceComprobacion!B:G,5,FALSE))) -> #N/A | AG10: =IF(J10="",0-IF(VLOOKUP(C10,BalanceComprobacion!B:G,6,FALSE)="",0,VLOOKUP(C10,BalanceComprobacion!B:G,6,FALSE)),DetalleSaldosBancosFinal1!J10-IF(VLOOKUP(DetalleSaldosBancosFinal1!C10,BalanceComprobacion!B:G,6,FALSE)="",0,VLOOKUP(DetalleSaldosBancosFinal1!C10,BalanceComprobacion!B:G,6,FALSE))) -> #N/A
A11: 2 | B11: 0 | C11: 1041102 | E11: 20130630 | F11: 20130630 | G11: 20130630 | H11: USD | J11: 111903.09 | L11: 40209.52 | N11: 40209.52 | O11: =+J11/L11 -> 2.7829999 | AF11: =IF(I11="",0-IF(VLOOKUP(C11,BalanceComprobacion!B:G,5,FALSE)="",0,VLOOKUP(C11,BalanceComprobacion!B:G,5,FALSE)),DetalleSaldosBancosFinal1!I11-IF(VLOOKUP(DetalleSaldosBancosFinal1!C11,BalanceComprobacion!B:G,5,FALSE)="",0,VLOOKUP(DetalleSaldosBancosFinal1!C11,BalanceComprobacion!B:G,5,FALSE))) -> #N/A | AG11: =IF(J11="",0-IF(VLOOKUP(C11,BalanceComprobacion!B:G,6,FALSE)="",0,VLOOKUP(C11,BalanceComprobacion!B:G,6,FALSE)),DetalleSaldosBancosFinal1!J11-IF(VLOOKUP(DetalleSaldosBancosFinal1!C11,BalanceComprobacion!B:G,6,FALSE)="",0,VLOOKUP(DetalleSaldosBancosFinal1!C11,BalanceComprobacion!B:G,6,FALSE))) -> #N/A
A12: 2 | B12: 1 | C12: 1041103 | E12: 20130630 | F12: 20130630 | G12: 20130630 | H12: USD | I12: 323742.16 | K12: 116328.48 | M12: 116328.48 | O12: =+I12/M12 -> 2.783 | AF12: =IF(I12="",0-IF(VLOOKUP(C12,BalanceComprobacion!B:G,5,FALSE)="",0,VLOOKUP(C12,BalanceComprobacion!B:G,5,FALSE)),DetalleSaldosBancosFinal1!I12-IF(VLOOKUP(DetalleSaldosBancosFinal1!C12,BalanceComprobacion!B:G,5,FALSE)="",0,VLOOKUP(DetalleSaldosBancosFinal1!C12,BalanceComprobacion!B:G,5,FALSE))) -> #N/A | AG12: =IF(J12="",0-IF(VLOOKUP(C12,BalanceComprobacion!B:G,6,FALSE)="",0,VLOOKUP(C12,BalanceComprobacion!B:G,6,FALSE)),DetalleSaldosBancosFinal1!J12-IF(VLOOKUP(DetalleSaldosBancosFinal1!C12,BalanceComprobacion!B:G,6,FALSE)="",0,VLOOKUP(DetalleSaldosBancosFinal1!C12,BalanceComprobacion!B:G,6,FALSE))) -> #N/A
A13: 2 | B13: 2 | C13: 1041106 | E13: 20130630 | F13: 20130630 | G13: 20130630 | H13: USD | I13: 24120.1 | K13: 8676.3 | M13: 8676.3 | O13: =+I13/M13 -> 2.7799984 | AF13: =IF(I13="",0-IF(VLOOKUP(C13,BalanceComprobacion!B:G,5,FALSE)="",0,VLOOKUP(C13,BalanceComprobacion!B:G,5,FALSE)),DetalleSaldosBancosFinal1!I13-IF(VLOOKUP(DetalleSaldosBancosFinal1!C13,BalanceComprobacion!B:G,5,FALSE)="",0,VLOOKUP(DetalleSaldosBancosFinal1!C13,BalanceComprobacion!B:G,5,FALSE))) -> #N/A | AG13: =IF(J13="",0-IF(VLOOKUP(C13,BalanceComprobacion!B:G,6,FALSE)="",0,VLOOKUP(C13,BalanceComprobacion!B:G,6,FALSE)),DetalleSaldosBancosFinal1!J13-IF(VLOOKUP(DetalleSaldosBancosFinal1!C13,BalanceComprobacion!B:G,6,FALSE)="",0,VLOOKUP(DetalleSaldosBancosFinal1!C13,BalanceComprobacion!B:G,6,FALSE))) -> #N/A
A14: 2 | B14: 3 | C14: 1041108 | E14: 20130630 | F14: 20130630 | G14: 20130630 | H14: USD | I14: 184969.64 | K14: 66535.84 | M14: 66535.84 | O14: =+I14/M14 -> 2.7800001 | AF14: =IF(I14="",0-IF(VLOOKUP(C14,BalanceComprobacion!B:G,5,FALSE)="",0,VLOOKUP(C14,BalanceComprobacion!B:G,5,FALSE)),DetalleSaldosBancosFinal1!I14-IF(VLOOKUP(DetalleSaldosBancosFinal1!C14,BalanceComprobacion!B:G,5,FALSE)="",0,VLOOKUP(DetalleSaldosBancosFinal1!C14,BalanceComprobacion!B:G,5,FALSE))) -> #N/A | AG14: =IF(J14="",0-IF(VLOOKUP(C14,BalanceComprobacion!B:G,6,FALSE)="",0,VLOOKUP(C14,BalanceComprobacion!B:G,6,FALSE)),DetalleSaldosBancosFinal1!J14-IF(VLOOKUP(DetalleSaldosBancosFinal1!C14,BalanceComprobacion!B:G,6,FALSE)="",0,VLOOKUP(DetalleSaldosBancosFinal1!C14,BalanceComprobacion!B:G,6,FALSE))) -> #N/A
A15: 2 | B15: 4 | C15: 1041109 | E15: 20130630 | F15: 20130630 | G15: 20130630 | H15: USD | J15: 2986548.4 | L15: 1073139.9 | N15: 1073139.9 | O15: =+I15/M15 -> #DIV/0! | AF15: =IF(I15="",0-IF(VLOOKUP(C15,BalanceComprobacion!B:G,5,FALSE)="",0,VLOOKUP(C15,BalanceComprobacion!B:G,5,FALSE)),DetalleSaldosBancosFinal1!I15-IF(VLOOKUP(DetalleSaldosBancosFinal1!C15,BalanceComprobacion!B:G,5,FALSE)="",0,VLOOKUP(DetalleSaldosBancosFinal1!C15,BalanceComprobacion!B:G,5,FALSE))) -> #N/A | AG15: =IF(J15="",0-IF(VLOOKUP(C15,BalanceComprobacion!B:G,6,FALSE)="",0,VLOOKUP(C15,BalanceComprobacion!B:G,6,FALSE)),DetalleSaldosBancosFinal1!J15-IF(VLOOKUP(DetalleSaldosBancosFinal1!C15,BalanceComprobacion!B:G,6,FALSE)="",0,VLOOKUP(DetalleSaldosBancosFinal1!C15,BalanceComprobacion!B:G,6,FALSE))) -> #N/A
A16: 2 | B16: 5 | C16: 1041111 | E16: 20130630 | F16: 20130630 | G16: 20130630 | H16: USD | J16: 97082.81 | L16: 34884.23 | N16: 34884.23 | AF16: =IF(I16="",0-IF(VLOOKUP(C16,BalanceComprobacion!B:G,5,FALSE)="",0,VLOOKUP(C16,BalanceComprobacion!B:G,5,FALSE)),DetalleSaldosBancosFinal1!I16-IF(VLOOKUP(DetalleSaldosBancosFinal1!C16,BalanceComprobacion!B:G,5,FALSE)="",0,VLOOKUP(DetalleSaldosBancosFinal1!C16,BalanceComprobacion!B:G,5,FALSE))) -> #N/A | AG16: =IF(J16="",0-IF(VLOOKUP(C16,BalanceComprobacion!B:G,6,FALSE)="",0,VLOOKUP(C16,BalanceComprobacion!B:G,6,FALSE)),DetalleSaldosBancosFinal1!J16-IF(VLOOKUP(DetalleSaldosBancosFinal1!C16,BalanceComprobacion!B:G,6,FALSE)="",0,VLOOKUP(DetalleSaldosBancosFinal1!C16,BalanceComprobacion!B:G,6,FALSE))) -> #N/A
A17: 2 | B17: 6 | C17: 1041112 | E17: 20130630 | F17: 20130630 | G17: 20130630 | H17: USD | I17: 76543.66 | K17: 27533.69 | M17: 27533.69 | AF17: =IF(I17="",0-IF(VLOOKUP(C17,BalanceComprobacion!B:G,5,FALSE)="",0,VLOOKUP(C17,BalanceComprobacion!B:G,5,FALSE)),DetalleSaldosBancosFinal1!I17-IF(VLOOKUP(DetalleSaldosBancosFinal1!C17,BalanceComprobacion!B:G,5,FALSE)="",0,VLOOKUP(DetalleSaldosBancosFinal1!C17,BalanceComprobacion!B:G,5,FALSE))) -> #N/A | AG17: =IF(J17="",0-IF(VLOOKUP(C17,BalanceComprobacion!B:G,6,FALSE)="",0,VLOOKUP(C17,BalanceComprobacion!B:G,6,FALSE)),DetalleSaldosBancosFinal1!J17-IF(VLOOKUP(DetalleSaldosBancosFinal1!C17,BalanceComprobacion!B:G,6,FALSE)="",0,VLOOKUP(DetalleSaldosBancosFinal1!C17,BalanceComprobacion!B:G,6,FALSE))) -> #N/A
A18: 2 | B18: 7 | C18: 1041113 | E18: 20130630 | F18: 20130630 | G18: 20130630 | H18: USD | J18: 58576.47 | L18: 21047.96 | N18: 21047.96 | AF18: =IF(I18="",0-IF(VLOOKUP(C18,BalanceComprobacion!B:G,5,FALSE)="",0,VLOOKUP(C18,BalanceComprobacion!B:G,5,FALSE)),DetalleSaldosBancosFinal1!I18-IF(VLOOKUP(DetalleSaldosBancosFinal1!C18,BalanceComprobacion!B:G,5,FALSE)="",0,VLOOKUP(DetalleSaldosBancosFinal1!C18,BalanceComprobacion!B:G,5,FALSE))) -> #N/A | AG18: =IF(J18="",0-IF(VLOOKUP(C18,BalanceComprobacion!B:G,6,FALSE)="",0,VLOOKUP(C18,BalanceComprobacion!B:G,6,FALSE)),DetalleSaldosBancosFinal1!J18-IF(VLOOKUP(DetalleSaldosBancosFinal1!C18,BalanceComprobacion!B:G,6,FALSE)="",0,VLOOKUP(DetalleSaldosBancosFinal1!C18,BalanceComprobacion!B:G,6,FALSE))) -> #N/A
A19: 2 | B19: 8 | C19: 1041104 | E19: 20130630 | F19: 20130630 | G19: 20130630 | H19: USD | I19: 64.33 | K19: 23.14 | M19: 23.14 | AF19: =IF(I19="",0-IF(VLOOKUP(C19,BalanceComprobacion!B:G,5,FALSE)="",0,VLOOKUP(C19,BalanceComprobacion!B:G,5,FALSE)),DetalleSaldosBancosFinal1!I19-IF(VLOOKUP(DetalleSaldosBancosFinal1!C19,BalanceComprobacion!B:G,5,FALSE)="",0,VLOOKUP(DetalleSaldosBancosFinal1!C19,BalanceComprobacion!B:G,5,FALSE))) -> 0 | AG19: =IF(J19="",0-IF(VLOOKUP(C19,BalanceComprobacion!B:G,6,FALSE)="",0,VLOOKUP(C19,BalanceComprobacion!B:G,6,FALSE)),DetalleSaldosBancosFinal1!J19-IF(VLOOKUP(DetalleSaldosBancosFinal1!C19,BalanceComprobacion!B:G,6,FALSE)="",0,VLOOKUP(DetalleSaldosBancosFinal1!C19,BalanceComprobacion!B:G,6,FALSE))) -> 0
A20: 2 | B20: 9 | C20: 9901 | D20: Cuenta de Cierre de Bancos USD | E20: 20130630 | F20: 20130630 | G20: 20130630 | H20: USD | I20: 2644670.9 | K20: 950184.19 | M20: 950184.19 | N20: 368689.88 | AF20: =IF(I20="",0-IF(VLOOKUP(C20,BalanceComprobacion!B:G,5,FALSE)="",0,VLOOKUP(C20,BalanceComprobacion!B:G,5,FALSE)),DetalleSaldosBancosFinal1!I20-IF(VLOOKUP(DetalleSaldosBancosFinal1!C20,BalanceComprobacion!B:G,5,FALSE)="",0,VLOOKUP(DetalleSaldosBancosFinal1!C20,BalanceComprobacion!B:G,5,FALSE))) -> #N/A | AG20: =IF(J20="",0-IF(VLOOKUP(C20,BalanceComprobacion!B:G,6,FALSE)="",0,VLOOKUP(C20,BalanceComprobacion!B:G,6,FALSE)),DetalleSaldosBancosFinal1!J20-IF(VLOOKUP(DetalleSaldosBancosFinal1!C20,BalanceComprobacion!B:G,6,FALSE)="",0,VLOOKUP(DetalleSaldosBancosFinal1!C20,BalanceComprobacion!B:G,6,FALSE))) -> #N/A

Sheet BalanceComprobacion
A1: NUM. | B1: CTA | D1: SUMAS DEL MAYOR | F1: SALDOS | H1: INVENTARIO | J1: RESULTADOS
A2: CTA. | B2: SAP | C2: D E S C R I P C I O N | D2: D E B E | E2: H A B E R | F2: DEUDOR | G2: ACREEDOR | H2: A C T I V O | I2: P A S I V O | J2: PERDIDAS | K2: GANANCIAS
A4: 10101001 | B4: =VLOOKUP(A4,#REF!,3,FALSE) -> #REF! | C4: CAJA SOLES | D4: 269843.79 | E4: 236702.83 | F4: 33140.96 | H4: 33140.96
A5: 10102001 | B5: =VLOOKUP(A5,#REF!,3,FALSE) -> #REF! | C5: CAJA DOLARES | D5: 48815.91 | E5: 48815.91
A6: 10201001 | B6: =VLOOKUP(A6,#REF!,3,FALSE) -> #REF! | C6: FONDOS FIJOS ÑAÑA | D6: 24234.37 | E6: 21734.37 | F6: 2500 | H6: 2500
A7: 10411001 | B7: =VLOOKUP(A7,#REF!,3,FALSE) -> #REF! | C7: BANCO SCOTIABANK GTIA ME 000-169 | D7: 2959201.7 | E7: 3071104.8 | G7: 111903.09 | I7: 111903.09
A8: 10411002 | B8: 1041104 | C8: BANCO SCOTIABANK CTA GARANT ME 0 | D8: 64.33 | F8: 64.33 | H8: 64.33
A9: 10411003 | B9: =VLOOKUP(A9,#REF!,3,FALSE) -> #REF! | C9: BANCO SCOTIABANK CTA DOLARES CTA | D9: =9200.86+330602.46 -> 339803.32 | E9: 16061.16 | F9: 323742.16 | H9: 323742.16
A10: 10411004 | B10: =VLOOKUP(A10,#REF!,3,FALSE) -> #REF! | C10: BANCO SCOTIABANK CTA CRED.DOC. M | D10: 535325.15 | E10: 670731.52 | G10: 135406.37 | I10: 135406.37
A12: 10412002 | B12: =VLOOKUP(A12,#REF!,3,FALSE) -> #REF! | C12: MI BANCO CTA CTE DOLARES 0187432 | D12: 45929.8 | E12: 21809.7 | F12: 24120.1 | H12: 24120.1
A13: 10413001 | B13: =VLOOKUP(A13,#REF!,3,FALSE) -> #REF! | C13: BCO DE CREDITO CTA.CTE.002-193-0 | D13: 24535546 | E13: 24371592 | F13: 163954 | H13: 163954
A14: 10413002 | B14: =VLOOKUP(A14,#REF!,3,FALSE) -> #REF! | C14: BANCO DE CREDITO ME 002-193-0015 | D14: 34442525 | E14: 37429073 | G14: 2986548.4 | I14: 2986548.4
A15: 10413003 | B15: =VLOOKUP(A15,#REF!,3,FALSE) -> #REF! | C15: OPALO BCO.CRED S/.191-1709699-0- | E15: 102576.83 | G15: 102576.83 | I15: 102576.83
A16: 10413004 | B16: =VLOOKUP(A16,#REF!,3,FALSE) -> #REF! | C16: OPALO BCO. CRED. $ 191-169455-1- | D16: 59664.92 | E16: 156747.73 | G16: 97082.81 | I16: 97082.81
A17: 10413005 | B17: =VLOOKUP(A17,#REF!,3,FALSE) -> #REF! | C17: BCO DE CREDITO CTA CTE ME $ 193- | D17: 269572.35 | E17: 84602.71 | F17: 184969.64 | H17: 184969.64
A18: 10415001 | B18: =VLOOKUP(A18,#REF!,3,FALSE) -> #REF! | C18: BANCO INTERBANK/EX LATINO CTA CT | D18: 76543.66 | F18: 76543.66 | H18: 76543.66
A19: 10415002 | B19: =VLOOKUP(A19,#REF!,3,FALSE) -> #REF! | C19: BANCO INTERBANK CTA CTE ME 003-0 | D19: 12292.92 | E19: 70869.39 | G19: 58576.47 | I19: 58576.47
A20: 10621001 | B20: =VLOOKUP(A20,#REF!,3,FALSE) -> #REF! | C20: DEPOSITO A PLAZO SCOTIABANK | D20: 515904.17 | F20: 515904.17 | H20: 515904.17
A21: 10711001 | B21: =VLOOKUP(A21,#REF!,3,FALSE) -> #REF! | C21: BANCO DE LA NACION CTA DETRACCIO | D21: 966505.29 | E21: 970292.98 | G21: 3787.69 | I21: 3787.69

Sheet Detalle_Saldos_Bancos)
A1: ParentKey | B1: LineNum | C1: AccountCode | D1: LineMemo | E1: DueDate | F1: TaxDate | G1: VatDate | H1: FCCurrency | I1: Debit | J1: Credit | K1: FCDebit | L1: FCCredit | M1: DebitSys | N1: CreditSys | O1: Reference2 | P1: AdditionalReference | Q1: BaseSum | R1: ContraAccount | S1: CostingCode | T1: GrossValue | U1: ProjectCode | V1: Reference1 | W1: ReferenceDate1 | X1: ReferenceDate2 | Y1: ShortName | Z1: SystemBaseAmount | AA1: SystemVatAmount | AB1: TaxGroup | AC1: VatAmount | AD1: VatLine | AE1: U_BPP_CTAD
A2: Correlativo | B2: Numero de Linea | C2: Cuenta Contable | D2: Observaciones | E2: Fecha de Contabilizacion | F2: Fecha de Documento | G2: Fecha de Vencimiento | H2: Moneda | I2: Debe Soles | J2: Haber Soles | K2: Debe Dolares | L2: Haber Dolares | M2: Debe Sistema | N2: Haber Sistema | O2: Reference2 | P2: AdditionalReference | Q2: BaseSum | R2: ContraAccount | S2: CostingCode | T2: GrossValue | U2: ProjectCode | V2: Reference1 | W2: ReferenceDate1 | X2: ReferenceDate2 | Y2: ShortName | Z2: SystemBaseAmount | AA2: SystemVatAmount | AB2: TaxGroup | AC2: VatAmount | AD2: VatLine | AE2: Cta Destino
A3: 1 | B3: 0 | C3: 1011101 | E3: 20130630 | F3: 20130630 | G3: 20130630 | I3: 33140.96
A4: 1 | B4: 1 | C4: 1020101 | E4: 20130630 | F4: 20130630 | G4: 20130630 | I4: 2500
A5: 1 | B5: 2 | C5: 1041107 | E5: 20130630 | F5: 20130630 | G5: 20130630 | I5: 163954
A6: 1 | B6: 3 | C6: 1041110 | E6: 20130630 | F6: 20130630 | G6: 20130630 | J6: 102576.83
A7: 1 | B7: 4 | C7: 1041101 | E7: 20130630 | F7: 20130630 | G7: 20130630 | J7: 135406.37
A8: 1 | B8: 5 | C8: 1042101 | E8: 20130630 | F8: 20130630 | G8: 20130630 | J8: 3787.69
A9: 1 | B9: 6 | C9: 1062101 | E9: 20130630 | F9: 20130630 | G9: 20130630 | I9: 515904.17
A10: 1 | B10: 6 | C10: 9901 | D10: Cuenta de Cierre de Bancos SOL | E10: 20130630 | F10: 20130630 | G10: 20130630 | J10: 473728.24
A11: 2 | B11: 0 | C11: 1041102 | E11: 20130630 | F11: 20130630 | G11: 20130630 | H11: USD | J11: 111903.09 | L11: 40209.52 | N11: 40209.52 | O11: =+J11/L11 -> 2.7829999
A12: 2 | B12: 1 | C12: 1041103 | E12: 20130630 | F12: 20130630 | G12: 20130630 | H12: USD | I12: 323742.16 | K12: 116328.48 | M12: 116328.48 | O12: =+I12/M12 -> 2.783
A13: 2 | B13: 2 | C13: 1041106 | E13: 20130630 | F13: 20130630 | G13: 20130630 | H13: USD | I13: 24120.1 | K13: 8676.3 | M13: 8676.3 | O13: =+I13/M13 -> 2.7799984
A14: 2 | B14: 3 | C14: 1041108 | E14: 20130630 | F14: 20130630 | G14: 20130630 | H14: USD | I14: 184969.64 | K14: 66535.84 | M14: 66535.84 | O14: =+I14/M14 -> 2.7800001
A15: 2 | B15: 4 | C15: 1041109 | E15: 20130630 | F15: 20130630 | G15: 20130630 | H15: USD | J15: 2986548.4 | L15: 1073139.9 | N15: 1073139.9 | O15: =+I15/M15 -> #DIV/0!
A16: 2 | B16: 5 | C16: 1041111 | E16: 20130630 | F16: 20130630 | G16: 20130630 | H16: USD | J16: 97082.81 | L16: 34884.23 | N16: 34884.23
A17: 2 | B17: 6 | C17: 1041112 | E17: 20130630 | F17: 20130630 | G17: 20130630 | H17: USD | I17: 76543.66 | K17: 27533.69 | M17: 27533.69
A18: 2 | B18: 7 | C18: 1041113 | E18: 20130630 | F18: 20130630 | G18: 20130630 | H18: USD | J18: 58576.47 | L18: 21047.96 | N18: 21047.96
A19: 2 | B19: 8 | C19: 1041114 | E19: 20130630 | F19: 20130630 | G19: 20130630 | H19: USD | I19: 64.33 | K19: 23.14 | M19: 23.14
A20: 2 | B20: 9 | C20: 9901 | D20: Cuenta de Cierre de Bancos USD | E20: 20130630 | F20: 20130630 | G20: 20130630 | H20: USD | I20: 2644670.9 | K20: 950184.19 | M20: 950184.19 | N20: 368689.88 | O20: =M20-N20 -> 581494.31
M22: =SUM(M12:M19) -> 219097.45 | N22: =SUM(N11:N20) -> 1537971.5 | O22: =M22-N22 -> -1318874.1
